2016-09-28 11:17:19,198 [Thread-3:7116] [django.request:124] [ERROR]- Internal Server Error: /lsinters/
Traceback (most recent call last):
  File "D:\python\Python27\lib\site-packages\django\core\handlers\exception.py", line 39, in inner
    response = get_response(request)
  File "D:\python\Python27\lib\site-packages\django\core\handlers\base.py", line 187, in _get_response
    response = self.process_exception_by_middleware(e, request)
  File "D:\python\Python27\lib\site-packages\django\core\handlers\base.py", line 185, in _get_response
    response = wrapped_callback(request, *callback_args, **callback_kwargs)
  File "F:\python-workspace\autotest\urlinter\views.py", line 29, in lsinters
    inters=parse()
  File "F:\python-workspace\autotest\utils\xml_util.py", line 18, in parse
    DOMTree = xml.dom.minidom.parse(xml_path)
  File "D:\python\Python27\lib\xml\dom\minidom.py", line 1918, in parse
    return expatbuilder.parse(file)
  File "D:\python\Python27\lib\xml\dom\expatbuilder.py", line 922, in parse
    fp = open(file, 'rb')
IOError: [Errno 2] No such file or directory: '../config/config.xml'
2016-09-28 11:17:19,394 [Thread-3:7116] [django.request:124] [ERROR]- Internal Server Error: /lsinters/
Traceback (most recent call last):
  File "D:\python\Python27\lib\site-packages\django\core\handlers\exception.py", line 39, in inner
    response = get_response(request)
  File "D:\python\Python27\lib\site-packages\django\utils\deprecation.py", line 133, in __call__
    response = self.get_response(request)
  File "D:\python\Python27\lib\site-packages\django\core\handlers\exception.py", line 41, in inner
    response = response_for_exception(request, exc)
  File "D:\python\Python27\lib\site-packages\django\core\handlers\exception.py", line 86, in response_for_exception
    response = handle_uncaught_exception(request, get_resolver(get_urlconf()), sys.exc_info())
  File "D:\python\Python27\lib\site-packages\django\core\handlers\exception.py", line 128, in handle_uncaught_exception
    return debug.technical_500_response(request, *exc_info)
  File "D:\python\Python27\lib\site-packages\django\views\debug.py", line 84, in technical_500_response
    html = reporter.get_traceback_html()
  File "D:\python\Python27\lib\site-packages\django\views\debug.py", line 317, in get_traceback_html
    return t.render(c)
  File "D:\python\Python27\lib\site-packages\django\template\base.py", line 208, in render
    return self._render(context)
  File "D:\python\Python27\lib\site-packages\django\template\base.py", line 199, in _render
    return self.nodelist.render(context)
  File "D:\python\Python27\lib\site-packages\django\template\base.py", line 994, in render
    bit = node.render_annotated(context)
  File "D:\python\Python27\lib\site-packages\django\template\base.py", line 961, in render_annotated
    return self.render(context)
  File "D:\python\Python27\lib\site-packages\django\template\defaulttags.py", line 315, in render
    return nodelist.render(context)
  File "D:\python\Python27\lib\site-packages\django\template\base.py", line 994, in render
    bit = node.render_annotated(context)
  File "D:\python\Python27\lib\site-packages\django\template\base.py", line 961, in render_annotated
    return self.render(context)
  File "D:\python\Python27\lib\site-packages\django\template\defaulttags.py", line 314, in render
    if match:
  File "D:\python\Python27\lib\site-packages\django\utils\functional.py", line 234, in inner
    self._setup()
  File "D:\python\Python27\lib\site-packages\django\utils\functional.py", line 380, in _setup
    self._wrapped = self._setupfunc()
  File "D:\python\Python27\lib\site-packages\django\contrib\auth\middleware.py", line 24, in <lambda>
    request.user = SimpleLazyObject(lambda: get_user(request))
  File "D:\python\Python27\lib\site-packages\django\contrib\auth\middleware.py", line 12, in get_user
    request._cached_user = auth.get_user(request)
  File "D:\python\Python27\lib\site-packages\django\contrib\auth\__init__.py", line 180, in get_user
    user_id = _get_user_session_key(request)
  File "D:\python\Python27\lib\site-packages\django\contrib\auth\__init__.py", line 59, in _get_user_session_key
    return get_user_model()._meta.pk.to_python(request.session[SESSION_KEY])
  File "D:\python\Python27\lib\site-packages\django\contrib\sessions\backends\base.py", line 57, in __getitem__
    return self._session[key]
  File "D:\python\Python27\lib\site-packages\django\contrib\sessions\backends\base.py", line 207, in _get_session
    self._session_cache = self.load()
  File "D:\python\Python27\lib\site-packages\django\contrib\sessions\backends\db.py", line 35, in load
    expire_date__gt=timezone.now()
  File "D:\python\Python27\lib\site-packages\django\db\models\manager.py", line 85, in manager_method
    return getattr(self.get_queryset(), name)(*args, **kwargs)
  File "D:\python\Python27\lib\site-packages\django\db\models\query.py", line 379, in get
    num = len(clone)
  File "D:\python\Python27\lib\site-packages\django\db\models\query.py", line 238, in __len__
    self._fetch_all()
  File "D:\python\Python27\lib\site-packages\django\db\models\query.py", line 1087, in _fetch_all
    self._result_cache = list(self.iterator())
  File "D:\python\Python27\lib\site-packages\django\db\models\query.py", line 54, in __iter__
    results = compiler.execute_sql()
  File "D:\python\Python27\lib\site-packages\django\db\models\sql\compiler.py", line 835, in execute_sql
    cursor.execute(sql, params)
  File "D:\python\Python27\lib\site-packages\django\db\backends\utils.py", line 79, in execute
    return super(CursorDebugWrapper, self).execute(sql, params)
  File "D:\python\Python27\lib\site-packages\django\db\backends\utils.py", line 64, in execute
    return self.cursor.execute(sql, params)
  File "D:\python\Python27\lib\site-packages\django\db\utils.py", line 94, in __exit__
    six.reraise(dj_exc_type, dj_exc_value, traceback)
  File "D:\python\Python27\lib\site-packages\django\db\backends\utils.py", line 64, in execute
    return self.cursor.execute(sql, params)
  File "D:\python\Python27\lib\site-packages\django\db\backends\sqlite3\base.py", line 337, in execute
    return Database.Cursor.execute(self, query, params)
OperationalError: no such table: django_session
2016-09-28 11:17:19,690 [Thread-3:7116] [django.request:124] [ERROR]- Internal Server Error: /lsinters/
Traceback (most recent call last):
  File "D:\python\Python27\lib\site-packages\django\core\handlers\exception.py", line 39, in inner
    response = get_response(request)
  File "D:\python\Python27\lib\site-packages\django\utils\deprecation.py", line 133, in __call__
    response = self.get_response(request)
  File "D:\python\Python27\lib\site-packages\django\core\handlers\exception.py", line 41, in inner
    response = response_for_exception(request, exc)
  File "D:\python\Python27\lib\site-packages\django\core\handlers\exception.py", line 86, in response_for_exception
    response = handle_uncaught_exception(request, get_resolver(get_urlconf()), sys.exc_info())
  File "D:\python\Python27\lib\site-packages\django\core\handlers\exception.py", line 128, in handle_uncaught_exception
    return debug.technical_500_response(request, *exc_info)
  File "D:\python\Python27\lib\site-packages\django\views\debug.py", line 84, in technical_500_response
    html = reporter.get_traceback_html()
  File "D:\python\Python27\lib\site-packages\django\views\debug.py", line 317, in get_traceback_html
    return t.render(c)
  File "D:\python\Python27\lib\site-packages\django\template\base.py", line 208, in render
    return self._render(context)
  File "D:\python\Python27\lib\site-packages\django\template\base.py", line 199, in _render
    return self.nodelist.render(context)
  File "D:\python\Python27\lib\site-packages\django\template\base.py", line 994, in render
    bit = node.render_annotated(context)
  File "D:\python\Python27\lib\site-packages\django\template\base.py", line 961, in render_annotated
    return self.render(context)
  File "D:\python\Python27\lib\site-packages\django\template\defaulttags.py", line 315, in render
    return nodelist.render(context)
  File "D:\python\Python27\lib\site-packages\django\template\base.py", line 994, in render
    bit = node.render_annotated(context)
  File "D:\python\Python27\lib\site-packages\django\template\base.py", line 961, in render_annotated
    return self.render(context)
  File "D:\python\Python27\lib\site-packages\django\template\defaulttags.py", line 314, in render
    if match:
  File "D:\python\Python27\lib\site-packages\django\utils\functional.py", line 234, in inner
    self._setup()
  File "D:\python\Python27\lib\site-packages\django\utils\functional.py", line 380, in _setup
    self._wrapped = self._setupfunc()
  File "D:\python\Python27\lib\site-packages\django\contrib\auth\middleware.py", line 24, in <lambda>
    request.user = SimpleLazyObject(lambda: get_user(request))
  File "D:\python\Python27\lib\site-packages\django\contrib\auth\middleware.py", line 12, in get_user
    request._cached_user = auth.get_user(request)
  File "D:\python\Python27\lib\site-packages\django\contrib\auth\__init__.py", line 180, in get_user
    user_id = _get_user_session_key(request)
  File "D:\python\Python27\lib\site-packages\django\contrib\auth\__init__.py", line 59, in _get_user_session_key
    return get_user_model()._meta.pk.to_python(request.session[SESSION_KEY])
  File "D:\python\Python27\lib\site-packages\django\contrib\sessions\backends\base.py", line 57, in __getitem__
    return self._session[key]
  File "D:\python\Python27\lib\site-packages\django\contrib\sessions\backends\base.py", line 207, in _get_session
    self._session_cache = self.load()
  File "D:\python\Python27\lib\site-packages\django\contrib\sessions\backends\db.py", line 35, in load
    expire_date__gt=timezone.now()
  File "D:\python\Python27\lib\site-packages\django\db\models\manager.py", line 85, in manager_method
    return getattr(self.get_queryset(), name)(*args, **kwargs)
  File "D:\python\Python27\lib\site-packages\django\db\models\query.py", line 379, in get
    num = len(clone)
  File "D:\python\Python27\lib\site-packages\django\db\models\query.py", line 238, in __len__
    self._fetch_all()
  File "D:\python\Python27\lib\site-packages\django\db\models\query.py", line 1087, in _fetch_all
    self._result_cache = list(self.iterator())
  File "D:\python\Python27\lib\site-packages\django\db\models\query.py", line 54, in __iter__
    results = compiler.execute_sql()
  File "D:\python\Python27\lib\site-packages\django\db\models\sql\compiler.py", line 835, in execute_sql
    cursor.execute(sql, params)
  File "D:\python\Python27\lib\site-packages\django\db\backends\utils.py", line 79, in execute
    return super(CursorDebugWrapper, self).execute(sql, params)
  File "D:\python\Python27\lib\site-packages\django\db\backends\utils.py", line 64, in execute
    return self.cursor.execute(sql, params)
  File "D:\python\Python27\lib\site-packages\django\db\utils.py", line 94, in __exit__
    six.reraise(dj_exc_type, dj_exc_value, traceback)
  File "D:\python\Python27\lib\site-packages\django\db\backends\utils.py", line 64, in execute
    return self.cursor.execute(sql, params)
  File "D:\python\Python27\lib\site-packages\django\db\backends\sqlite3\base.py", line 337, in execute
    return Database.Cursor.execute(self, query, params)
OperationalError: no such table: django_session
2016-09-28 11:17:19,832 [Thread-3:7116] [django.request:124] [ERROR]- Internal Server Error: /lsinters/
Traceback (most recent call last):
  File "D:\python\Python27\lib\site-packages\django\core\handlers\exception.py", line 39, in inner
    response = get_response(request)
  File "D:\python\Python27\lib\site-packages\django\utils\deprecation.py", line 133, in __call__
    response = self.get_response(request)
  File "D:\python\Python27\lib\site-packages\django\core\handlers\exception.py", line 41, in inner
    response = response_for_exception(request, exc)
  File "D:\python\Python27\lib\site-packages\django\core\handlers\exception.py", line 86, in response_for_exception
    response = handle_uncaught_exception(request, get_resolver(get_urlconf()), sys.exc_info())
  File "D:\python\Python27\lib\site-packages\django\core\handlers\exception.py", line 128, in handle_uncaught_exception
    return debug.technical_500_response(request, *exc_info)
  File "D:\python\Python27\lib\site-packages\django\views\debug.py", line 84, in technical_500_response
    html = reporter.get_traceback_html()
  File "D:\python\Python27\lib\site-packages\django\views\debug.py", line 317, in get_traceback_html
    return t.render(c)
  File "D:\python\Python27\lib\site-packages\django\template\base.py", line 208, in render
    return self._render(context)
  File "D:\python\Python27\lib\site-packages\django\template\base.py", line 199, in _render
    return self.nodelist.render(context)
  File "D:\python\Python27\lib\site-packages\django\template\base.py", line 994, in render
    bit = node.render_annotated(context)
  File "D:\python\Python27\lib\site-packages\django\template\base.py", line 961, in render_annotated
    return self.render(context)
  File "D:\python\Python27\lib\site-packages\django\template\defaulttags.py", line 315, in render
    return nodelist.render(context)
  File "D:\python\Python27\lib\site-packages\django\template\base.py", line 994, in render
    bit = node.render_annotated(context)
  File "D:\python\Python27\lib\site-packages\django\template\base.py", line 961, in render_annotated
    return self.render(context)
  File "D:\python\Python27\lib\site-packages\django\template\defaulttags.py", line 314, in render
    if match:
  File "D:\python\Python27\lib\site-packages\django\utils\functional.py", line 234, in inner
    self._setup()
  File "D:\python\Python27\lib\site-packages\django\utils\functional.py", line 380, in _setup
    self._wrapped = self._setupfunc()
  File "D:\python\Python27\lib\site-packages\django\contrib\auth\middleware.py", line 24, in <lambda>
    request.user = SimpleLazyObject(lambda: get_user(request))
  File "D:\python\Python27\lib\site-packages\django\contrib\auth\middleware.py", line 12, in get_user
    request._cached_user = auth.get_user(request)
  File "D:\python\Python27\lib\site-packages\django\contrib\auth\__init__.py", line 180, in get_user
    user_id = _get_user_session_key(request)
  File "D:\python\Python27\lib\site-packages\django\contrib\auth\__init__.py", line 59, in _get_user_session_key
    return get_user_model()._meta.pk.to_python(request.session[SESSION_KEY])
  File "D:\python\Python27\lib\site-packages\django\contrib\sessions\backends\base.py", line 57, in __getitem__
    return self._session[key]
  File "D:\python\Python27\lib\site-packages\django\contrib\sessions\backends\base.py", line 207, in _get_session
    self._session_cache = self.load()
  File "D:\python\Python27\lib\site-packages\django\contrib\sessions\backends\db.py", line 35, in load
    expire_date__gt=timezone.now()
  File "D:\python\Python27\lib\site-packages\django\db\models\manager.py", line 85, in manager_method
    return getattr(self.get_queryset(), name)(*args, **kwargs)
  File "D:\python\Python27\lib\site-packages\django\db\models\query.py", line 379, in get
    num = len(clone)
  File "D:\python\Python27\lib\site-packages\django\db\models\query.py", line 238, in __len__
    self._fetch_all()
  File "D:\python\Python27\lib\site-packages\django\db\models\query.py", line 1087, in _fetch_all
    self._result_cache = list(self.iterator())
  File "D:\python\Python27\lib\site-packages\django\db\models\query.py", line 54, in __iter__
    results = compiler.execute_sql()
  File "D:\python\Python27\lib\site-packages\django\db\models\sql\compiler.py", line 835, in execute_sql
    cursor.execute(sql, params)
  File "D:\python\Python27\lib\site-packages\django\db\backends\utils.py", line 79, in execute
    return super(CursorDebugWrapper, self).execute(sql, params)
  File "D:\python\Python27\lib\site-packages\django\db\backends\utils.py", line 64, in execute
    return self.cursor.execute(sql, params)
  File "D:\python\Python27\lib\site-packages\django\db\utils.py", line 94, in __exit__
    six.reraise(dj_exc_type, dj_exc_value, traceback)
  File "D:\python\Python27\lib\site-packages\django\db\backends\utils.py", line 64, in execute
    return self.cursor.execute(sql, params)
  File "D:\python\Python27\lib\site-packages\django\db\backends\sqlite3\base.py", line 337, in execute
    return Database.Cursor.execute(self, query, params)
OperationalError: no such table: django_session
2016-09-28 11:17:19,976 [Thread-3:7116] [django.request:124] [ERROR]- Internal Server Error: /lsinters/
Traceback (most recent call last):
  File "D:\python\Python27\lib\site-packages\django\core\handlers\exception.py", line 39, in inner
    response = get_response(request)
  File "D:\python\Python27\lib\site-packages\django\utils\deprecation.py", line 133, in __call__
    response = self.get_response(request)
  File "D:\python\Python27\lib\site-packages\django\core\handlers\exception.py", line 41, in inner
    response = response_for_exception(request, exc)
  File "D:\python\Python27\lib\site-packages\django\core\handlers\exception.py", line 86, in response_for_exception
    response = handle_uncaught_exception(request, get_resolver(get_urlconf()), sys.exc_info())
  File "D:\python\Python27\lib\site-packages\django\core\handlers\exception.py", line 128, in handle_uncaught_exception
    return debug.technical_500_response(request, *exc_info)
  File "D:\python\Python27\lib\site-packages\django\views\debug.py", line 84, in technical_500_response
    html = reporter.get_traceback_html()
  File "D:\python\Python27\lib\site-packages\django\views\debug.py", line 317, in get_traceback_html
    return t.render(c)
  File "D:\python\Python27\lib\site-packages\django\template\base.py", line 208, in render
    return self._render(context)
  File "D:\python\Python27\lib\site-packages\django\template\base.py", line 199, in _render
    return self.nodelist.render(context)
  File "D:\python\Python27\lib\site-packages\django\template\base.py", line 994, in render
    bit = node.render_annotated(context)
  File "D:\python\Python27\lib\site-packages\django\template\base.py", line 961, in render_annotated
    return self.render(context)
  File "D:\python\Python27\lib\site-packages\django\template\defaulttags.py", line 315, in render
    return nodelist.render(context)
  File "D:\python\Python27\lib\site-packages\django\template\base.py", line 994, in render
    bit = node.render_annotated(context)
  File "D:\python\Python27\lib\site-packages\django\template\base.py", line 961, in render_annotated
    return self.render(context)
  File "D:\python\Python27\lib\site-packages\django\template\defaulttags.py", line 314, in render
    if match:
  File "D:\python\Python27\lib\site-packages\django\utils\functional.py", line 234, in inner
    self._setup()
  File "D:\python\Python27\lib\site-packages\django\utils\functional.py", line 380, in _setup
    self._wrapped = self._setupfunc()
  File "D:\python\Python27\lib\site-packages\django\contrib\auth\middleware.py", line 24, in <lambda>
    request.user = SimpleLazyObject(lambda: get_user(request))
  File "D:\python\Python27\lib\site-packages\django\contrib\auth\middleware.py", line 12, in get_user
    request._cached_user = auth.get_user(request)
  File "D:\python\Python27\lib\site-packages\django\contrib\auth\__init__.py", line 180, in get_user
    user_id = _get_user_session_key(request)
  File "D:\python\Python27\lib\site-packages\django\contrib\auth\__init__.py", line 59, in _get_user_session_key
    return get_user_model()._meta.pk.to_python(request.session[SESSION_KEY])
  File "D:\python\Python27\lib\site-packages\django\contrib\sessions\backends\base.py", line 57, in __getitem__
    return self._session[key]
  File "D:\python\Python27\lib\site-packages\django\contrib\sessions\backends\base.py", line 207, in _get_session
    self._session_cache = self.load()
  File "D:\python\Python27\lib\site-packages\django\contrib\sessions\backends\db.py", line 35, in load
    expire_date__gt=timezone.now()
  File "D:\python\Python27\lib\site-packages\django\db\models\manager.py", line 85, in manager_method
    return getattr(self.get_queryset(), name)(*args, **kwargs)
  File "D:\python\Python27\lib\site-packages\django\db\models\query.py", line 379, in get
    num = len(clone)
  File "D:\python\Python27\lib\site-packages\django\db\models\query.py", line 238, in __len__
    self._fetch_all()
  File "D:\python\Python27\lib\site-packages\django\db\models\query.py", line 1087, in _fetch_all
    self._result_cache = list(self.iterator())
  File "D:\python\Python27\lib\site-packages\django\db\models\query.py", line 54, in __iter__
    results = compiler.execute_sql()
  File "D:\python\Python27\lib\site-packages\django\db\models\sql\compiler.py", line 835, in execute_sql
    cursor.execute(sql, params)
  File "D:\python\Python27\lib\site-packages\django\db\backends\utils.py", line 79, in execute
    return super(CursorDebugWrapper, self).execute(sql, params)
  File "D:\python\Python27\lib\site-packages\django\db\backends\utils.py", line 64, in execute
    return self.cursor.execute(sql, params)
  File "D:\python\Python27\lib\site-packages\django\db\utils.py", line 94, in __exit__
    six.reraise(dj_exc_type, dj_exc_value, traceback)
  File "D:\python\Python27\lib\site-packages\django\db\backends\utils.py", line 64, in execute
    return self.cursor.execute(sql, params)
  File "D:\python\Python27\lib\site-packages\django\db\backends\sqlite3\base.py", line 337, in execute
    return Database.Cursor.execute(self, query, params)
OperationalError: no such table: django_session
2016-09-28 11:17:20,118 [Thread-3:7116] [django.request:124] [ERROR]- Internal Server Error: /lsinters/
Traceback (most recent call last):
  File "D:\python\Python27\lib\site-packages\django\core\handlers\exception.py", line 39, in inner
    response = get_response(request)
  File "D:\python\Python27\lib\site-packages\django\utils\deprecation.py", line 133, in __call__
    response = self.get_response(request)
  File "D:\python\Python27\lib\site-packages\django\core\handlers\exception.py", line 41, in inner
    response = response_for_exception(request, exc)
  File "D:\python\Python27\lib\site-packages\django\core\handlers\exception.py", line 86, in response_for_exception
    response = handle_uncaught_exception(request, get_resolver(get_urlconf()), sys.exc_info())
  File "D:\python\Python27\lib\site-packages\django\core\handlers\exception.py", line 128, in handle_uncaught_exception
    return debug.technical_500_response(request, *exc_info)
  File "D:\python\Python27\lib\site-packages\django\views\debug.py", line 84, in technical_500_response
    html = reporter.get_traceback_html()
  File "D:\python\Python27\lib\site-packages\django\views\debug.py", line 317, in get_traceback_html
    return t.render(c)
  File "D:\python\Python27\lib\site-packages\django\template\base.py", line 208, in render
    return self._render(context)
  File "D:\python\Python27\lib\site-packages\django\template\base.py", line 199, in _render
    return self.nodelist.render(context)
  File "D:\python\Python27\lib\site-packages\django\template\base.py", line 994, in render
    bit = node.render_annotated(context)
  File "D:\python\Python27\lib\site-packages\django\template\base.py", line 961, in render_annotated
    return self.render(context)
  File "D:\python\Python27\lib\site-packages\django\template\defaulttags.py", line 315, in render
    return nodelist.render(context)
  File "D:\python\Python27\lib\site-packages\django\template\base.py", line 994, in render
    bit = node.render_annotated(context)
  File "D:\python\Python27\lib\site-packages\django\template\base.py", line 961, in render_annotated
    return self.render(context)
  File "D:\python\Python27\lib\site-packages\django\template\defaulttags.py", line 314, in render
    if match:
  File "D:\python\Python27\lib\site-packages\django\utils\functional.py", line 234, in inner
    self._setup()
  File "D:\python\Python27\lib\site-packages\django\utils\functional.py", line 380, in _setup
    self._wrapped = self._setupfunc()
  File "D:\python\Python27\lib\site-packages\django\contrib\auth\middleware.py", line 24, in <lambda>
    request.user = SimpleLazyObject(lambda: get_user(request))
  File "D:\python\Python27\lib\site-packages\django\contrib\auth\middleware.py", line 12, in get_user
    request._cached_user = auth.get_user(request)
  File "D:\python\Python27\lib\site-packages\django\contrib\auth\__init__.py", line 180, in get_user
    user_id = _get_user_session_key(request)
  File "D:\python\Python27\lib\site-packages\django\contrib\auth\__init__.py", line 59, in _get_user_session_key
    return get_user_model()._meta.pk.to_python(request.session[SESSION_KEY])
  File "D:\python\Python27\lib\site-packages\django\contrib\sessions\backends\base.py", line 57, in __getitem__
    return self._session[key]
  File "D:\python\Python27\lib\site-packages\django\contrib\sessions\backends\base.py", line 207, in _get_session
    self._session_cache = self.load()
  File "D:\python\Python27\lib\site-packages\django\contrib\sessions\backends\db.py", line 35, in load
    expire_date__gt=timezone.now()
  File "D:\python\Python27\lib\site-packages\django\db\models\manager.py", line 85, in manager_method
    return getattr(self.get_queryset(), name)(*args, **kwargs)
  File "D:\python\Python27\lib\site-packages\django\db\models\query.py", line 379, in get
    num = len(clone)
  File "D:\python\Python27\lib\site-packages\django\db\models\query.py", line 238, in __len__
    self._fetch_all()
  File "D:\python\Python27\lib\site-packages\django\db\models\query.py", line 1087, in _fetch_all
    self._result_cache = list(self.iterator())
  File "D:\python\Python27\lib\site-packages\django\db\models\query.py", line 54, in __iter__
    results = compiler.execute_sql()
  File "D:\python\Python27\lib\site-packages\django\db\models\sql\compiler.py", line 835, in execute_sql
    cursor.execute(sql, params)
  File "D:\python\Python27\lib\site-packages\django\db\backends\utils.py", line 79, in execute
    return super(CursorDebugWrapper, self).execute(sql, params)
  File "D:\python\Python27\lib\site-packages\django\db\backends\utils.py", line 64, in execute
    return self.cursor.execute(sql, params)
  File "D:\python\Python27\lib\site-packages\django\db\utils.py", line 94, in __exit__
    six.reraise(dj_exc_type, dj_exc_value, traceback)
  File "D:\python\Python27\lib\site-packages\django\db\backends\utils.py", line 64, in execute
    return self.cursor.execute(sql, params)
  File "D:\python\Python27\lib\site-packages\django\db\backends\sqlite3\base.py", line 337, in execute
    return Database.Cursor.execute(self, query, params)
OperationalError: no such table: django_session
2016-09-28 11:17:20,282 [Thread-3:7116] [django.request:124] [ERROR]- Internal Server Error: /lsinters/
Traceback (most recent call last):
  File "D:\python\Python27\lib\site-packages\django\core\handlers\exception.py", line 39, in inner
    response = get_response(request)
  File "D:\python\Python27\lib\site-packages\django\utils\deprecation.py", line 133, in __call__
    response = self.get_response(request)
  File "D:\python\Python27\lib\site-packages\django\core\handlers\exception.py", line 41, in inner
    response = response_for_exception(request, exc)
  File "D:\python\Python27\lib\site-packages\django\core\handlers\exception.py", line 86, in response_for_exception
    response = handle_uncaught_exception(request, get_resolver(get_urlconf()), sys.exc_info())
  File "D:\python\Python27\lib\site-packages\django\core\handlers\exception.py", line 128, in handle_uncaught_exception
    return debug.technical_500_response(request, *exc_info)
  File "D:\python\Python27\lib\site-packages\django\views\debug.py", line 84, in technical_500_response
    html = reporter.get_traceback_html()
  File "D:\python\Python27\lib\site-packages\django\views\debug.py", line 317, in get_traceback_html
    return t.render(c)
  File "D:\python\Python27\lib\site-packages\django\template\base.py", line 208, in render
    return self._render(context)
  File "D:\python\Python27\lib\site-packages\django\template\base.py", line 199, in _render
    return self.nodelist.render(context)
  File "D:\python\Python27\lib\site-packages\django\template\base.py", line 994, in render
    bit = node.render_annotated(context)
  File "D:\python\Python27\lib\site-packages\django\template\base.py", line 961, in render_annotated
    return self.render(context)
  File "D:\python\Python27\lib\site-packages\django\template\defaulttags.py", line 315, in render
    return nodelist.render(context)
  File "D:\python\Python27\lib\site-packages\django\template\base.py", line 994, in render
    bit = node.render_annotated(context)
  File "D:\python\Python27\lib\site-packages\django\template\base.py", line 961, in render_annotated
    return self.render(context)
  File "D:\python\Python27\lib\site-packages\django\template\defaulttags.py", line 314, in render
    if match:
  File "D:\python\Python27\lib\site-packages\django\utils\functional.py", line 234, in inner
    self._setup()
  File "D:\python\Python27\lib\site-packages\django\utils\functional.py", line 380, in _setup
    self._wrapped = self._setupfunc()
  File "D:\python\Python27\lib\site-packages\django\contrib\auth\middleware.py", line 24, in <lambda>
    request.user = SimpleLazyObject(lambda: get_user(request))
  File "D:\python\Python27\lib\site-packages\django\contrib\auth\middleware.py", line 12, in get_user
    request._cached_user = auth.get_user(request)
  File "D:\python\Python27\lib\site-packages\django\contrib\auth\__init__.py", line 180, in get_user
    user_id = _get_user_session_key(request)
  File "D:\python\Python27\lib\site-packages\django\contrib\auth\__init__.py", line 59, in _get_user_session_key
    return get_user_model()._meta.pk.to_python(request.session[SESSION_KEY])
  File "D:\python\Python27\lib\site-packages\django\contrib\sessions\backends\base.py", line 57, in __getitem__
    return self._session[key]
  File "D:\python\Python27\lib\site-packages\django\contrib\sessions\backends\base.py", line 207, in _get_session
    self._session_cache = self.load()
  File "D:\python\Python27\lib\site-packages\django\contrib\sessions\backends\db.py", line 35, in load
    expire_date__gt=timezone.now()
  File "D:\python\Python27\lib\site-packages\django\db\models\manager.py", line 85, in manager_method
    return getattr(self.get_queryset(), name)(*args, **kwargs)
  File "D:\python\Python27\lib\site-packages\django\db\models\query.py", line 379, in get
    num = len(clone)
  File "D:\python\Python27\lib\site-packages\django\db\models\query.py", line 238, in __len__
    self._fetch_all()
  File "D:\python\Python27\lib\site-packages\django\db\models\query.py", line 1087, in _fetch_all
    self._result_cache = list(self.iterator())
  File "D:\python\Python27\lib\site-packages\django\db\models\query.py", line 54, in __iter__
    results = compiler.execute_sql()
  File "D:\python\Python27\lib\site-packages\django\db\models\sql\compiler.py", line 835, in execute_sql
    cursor.execute(sql, params)
  File "D:\python\Python27\lib\site-packages\django\db\backends\utils.py", line 79, in execute
    return super(CursorDebugWrapper, self).execute(sql, params)
  File "D:\python\Python27\lib\site-packages\django\db\backends\utils.py", line 64, in execute
    return self.cursor.execute(sql, params)
  File "D:\python\Python27\lib\site-packages\django\db\utils.py", line 94, in __exit__
    six.reraise(dj_exc_type, dj_exc_value, traceback)
  File "D:\python\Python27\lib\site-packages\django\db\backends\utils.py", line 64, in execute
    return self.cursor.execute(sql, params)
  File "D:\python\Python27\lib\site-packages\django\db\backends\sqlite3\base.py", line 337, in execute
    return Database.Cursor.execute(self, query, params)
OperationalError: no such table: django_session
2016-09-28 11:17:20,456 [Thread-3:7116] [django.request:124] [ERROR]- Internal Server Error: /lsinters/
Traceback (most recent call last):
  File "D:\python\Python27\lib\site-packages\django\core\handlers\exception.py", line 39, in inner
    response = get_response(request)
  File "D:\python\Python27\lib\site-packages\django\utils\deprecation.py", line 133, in __call__
    response = self.get_response(request)
  File "D:\python\Python27\lib\site-packages\django\core\handlers\exception.py", line 41, in inner
    response = response_for_exception(request, exc)
  File "D:\python\Python27\lib\site-packages\django\core\handlers\exception.py", line 86, in response_for_exception
    response = handle_uncaught_exception(request, get_resolver(get_urlconf()), sys.exc_info())
  File "D:\python\Python27\lib\site-packages\django\core\handlers\exception.py", line 128, in handle_uncaught_exception
    return debug.technical_500_response(request, *exc_info)
  File "D:\python\Python27\lib\site-packages\django\views\debug.py", line 84, in technical_500_response
    html = reporter.get_traceback_html()
  File "D:\python\Python27\lib\site-packages\django\views\debug.py", line 317, in get_traceback_html
    return t.render(c)
  File "D:\python\Python27\lib\site-packages\django\template\base.py", line 208, in render
    return self._render(context)
  File "D:\python\Python27\lib\site-packages\django\template\base.py", line 199, in _render
    return self.nodelist.render(context)
  File "D:\python\Python27\lib\site-packages\django\template\base.py", line 994, in render
    bit = node.render_annotated(context)
  File "D:\python\Python27\lib\site-packages\django\template\base.py", line 961, in render_annotated
    return self.render(context)
  File "D:\python\Python27\lib\site-packages\django\template\defaulttags.py", line 315, in render
    return nodelist.render(context)
  File "D:\python\Python27\lib\site-packages\django\template\base.py", line 994, in render
    bit = node.render_annotated(context)
  File "D:\python\Python27\lib\site-packages\django\template\base.py", line 961, in render_annotated
    return self.render(context)
  File "D:\python\Python27\lib\site-packages\django\template\defaulttags.py", line 314, in render
    if match:
  File "D:\python\Python27\lib\site-packages\django\utils\functional.py", line 234, in inner
    self._setup()
  File "D:\python\Python27\lib\site-packages\django\utils\functional.py", line 380, in _setup
    self._wrapped = self._setupfunc()
  File "D:\python\Python27\lib\site-packages\django\contrib\auth\middleware.py", line 24, in <lambda>
    request.user = SimpleLazyObject(lambda: get_user(request))
  File "D:\python\Python27\lib\site-packages\django\contrib\auth\middleware.py", line 12, in get_user
    request._cached_user = auth.get_user(request)
  File "D:\python\Python27\lib\site-packages\django\contrib\auth\__init__.py", line 180, in get_user
    user_id = _get_user_session_key(request)
  File "D:\python\Python27\lib\site-packages\django\contrib\auth\__init__.py", line 59, in _get_user_session_key
    return get_user_model()._meta.pk.to_python(request.session[SESSION_KEY])
  File "D:\python\Python27\lib\site-packages\django\contrib\sessions\backends\base.py", line 57, in __getitem__
    return self._session[key]
  File "D:\python\Python27\lib\site-packages\django\contrib\sessions\backends\base.py", line 207, in _get_session
    self._session_cache = self.load()
  File "D:\python\Python27\lib\site-packages\django\contrib\sessions\backends\db.py", line 35, in load
    expire_date__gt=timezone.now()
  File "D:\python\Python27\lib\site-packages\django\db\models\manager.py", line 85, in manager_method
    return getattr(self.get_queryset(), name)(*args, **kwargs)
  File "D:\python\Python27\lib\site-packages\django\db\models\query.py", line 379, in get
    num = len(clone)
  File "D:\python\Python27\lib\site-packages\django\db\models\query.py", line 238, in __len__
    self._fetch_all()
  File "D:\python\Python27\lib\site-packages\django\db\models\query.py", line 1087, in _fetch_all
    self._result_cache = list(self.iterator())
  File "D:\python\Python27\lib\site-packages\django\db\models\query.py", line 54, in __iter__
    results = compiler.execute_sql()
  File "D:\python\Python27\lib\site-packages\django\db\models\sql\compiler.py", line 835, in execute_sql
    cursor.execute(sql, params)
  File "D:\python\Python27\lib\site-packages\django\db\backends\utils.py", line 79, in execute
    return super(CursorDebugWrapper, self).execute(sql, params)
  File "D:\python\Python27\lib\site-packages\django\db\backends\utils.py", line 64, in execute
    return self.cursor.execute(sql, params)
  File "D:\python\Python27\lib\site-packages\django\db\utils.py", line 94, in __exit__
    six.reraise(dj_exc_type, dj_exc_value, traceback)
  File "D:\python\Python27\lib\site-packages\django\db\backends\utils.py", line 64, in execute
    return self.cursor.execute(sql, params)
  File "D:\python\Python27\lib\site-packages\django\db\backends\sqlite3\base.py", line 337, in execute
    return Database.Cursor.execute(self, query, params)
OperationalError: no such table: django_session
2016-09-28 11:22:25,073 [Thread-5:5292] [django.request:124] [ERROR]- Internal Server Error: /lsinters/
Traceback (most recent call last):
  File "D:\python\Python27\lib\site-packages\django\core\handlers\exception.py", line 39, in inner
    response = get_response(request)
  File "D:\python\Python27\lib\site-packages\django\core\handlers\base.py", line 187, in _get_response
    response = self.process_exception_by_middleware(e, request)
  File "D:\python\Python27\lib\site-packages\django\core\handlers\base.py", line 185, in _get_response
    response = wrapped_callback(request, *callback_args, **callback_kwargs)
  File "F:\python-workspace\autotest\urlinter\views.py", line 29, in lsinters
    inters=parse()
  File "F:\python-workspace\autotest\utils\xml_util.py", line 18, in parse
    DOMTree = xml.dom.minidom.parse(xml_path)
  File "D:\python\Python27\lib\xml\dom\minidom.py", line 1918, in parse
    return expatbuilder.parse(file)
  File "D:\python\Python27\lib\xml\dom\expatbuilder.py", line 922, in parse
    fp = open(file, 'rb')
IOError: [Errno 2] No such file or directory: '../config/config.xml'
2016-09-28 11:29:12,538 [Thread-2:7104] [django.request:124] [ERROR]- Internal Server Error: /lsinters/
Traceback (most recent call last):
  File "D:\python\Python27\lib\site-packages\django\core\handlers\exception.py", line 39, in inner
    response = get_response(request)
  File "D:\python\Python27\lib\site-packages\django\core\handlers\base.py", line 187, in _get_response
    response = self.process_exception_by_middleware(e, request)
  File "D:\python\Python27\lib\site-packages\django\core\handlers\base.py", line 185, in _get_response
    response = wrapped_callback(request, *callback_args, **callback_kwargs)
  File "F:\python-workspace\autotest\urlinter\views.py", line 29, in lsinters
    inters=parse()
  File "F:\python-workspace\autotest\utils\xml_util.py", line 19, in parse
    DOMTree = xml.dom.minidom.parse(xml_path)
  File "D:\python\Python27\lib\xml\dom\minidom.py", line 1918, in parse
    return expatbuilder.parse(file)
  File "D:\python\Python27\lib\xml\dom\expatbuilder.py", line 922, in parse
    fp = open(file, 'rb')
IOError: [Errno 2] No such file or directory: 'F:\\python-workspace\\autotest\\configconfig.xml'
2016-09-28 11:29:31,132 [Thread-2:3076] [django.request:124] [ERROR]- Internal Server Error: /lsinters/
Traceback (most recent call last):
  File "D:\python\Python27\lib\site-packages\django\core\handlers\exception.py", line 39, in inner
    response = get_response(request)
  File "D:\python\Python27\lib\site-packages\django\core\handlers\base.py", line 187, in _get_response
    response = self.process_exception_by_middleware(e, request)
  File "D:\python\Python27\lib\site-packages\django\core\handlers\base.py", line 185, in _get_response
    response = wrapped_callback(request, *callback_args, **callback_kwargs)
  File "F:\python-workspace\autotest\urlinter\views.py", line 32, in lsinters
    return render(request, 'inters.html', ctx)
  File "D:\python\Python27\lib\site-packages\django\shortcuts.py", line 30, in render
    content = loader.render_to_string(template_name, context, request, using=using)
  File "D:\python\Python27\lib\site-packages\django\template\loader.py", line 67, in render_to_string
    template = get_template(template_name, using=using)
  File "D:\python\Python27\lib\site-packages\django\template\loader.py", line 21, in get_template
    return engine.get_template(template_name)
  File "D:\python\Python27\lib\site-packages\django\template\backends\django.py", line 39, in get_template
    return Template(self.engine.get_template(template_name), self)
  File "D:\python\Python27\lib\site-packages\django\template\engine.py", line 160, in get_template
    template, origin = self.find_template(template_name)
  File "D:\python\Python27\lib\site-packages\django\template\engine.py", line 134, in find_template
    name, template_dirs=dirs, skip=skip,
  File "D:\python\Python27\lib\site-packages\django\template\loaders\base.py", line 44, in get_template
    contents, origin, origin.template_name, self.engine,
  File "D:\python\Python27\lib\site-packages\django\template\base.py", line 191, in __init__
    self.nodelist = self.compile_nodelist()
  File "D:\python\Python27\lib\site-packages\django\template\base.py", line 233, in compile_nodelist
    return parser.parse()
  File "D:\python\Python27\lib\site-packages\django\template\base.py", line 518, in parse
    raise self.error(token, e)
TemplateSyntaxError: Could not parse the remainder: '['url']' from 'inter['url']'
2016-09-28 11:32:21,607 [Thread-4:8132] [django.request:124] [ERROR]- Internal Server Error: /lsinters/
Traceback (most recent call last):
  File "D:\python\Python27\lib\site-packages\django\core\handlers\exception.py", line 39, in inner
    response = get_response(request)
  File "D:\python\Python27\lib\site-packages\django\core\handlers\base.py", line 187, in _get_response
    response = self.process_exception_by_middleware(e, request)
  File "D:\python\Python27\lib\site-packages\django\core\handlers\base.py", line 185, in _get_response
    response = wrapped_callback(request, *callback_args, **callback_kwargs)
  File "F:\python-workspace\autotest\urlinter\views.py", line 32, in lsinters
    return render(request, 'inters.html', ctx)
  File "D:\python\Python27\lib\site-packages\django\shortcuts.py", line 30, in render
    content = loader.render_to_string(template_name, context, request, using=using)
  File "D:\python\Python27\lib\site-packages\django\template\loader.py", line 67, in render_to_string
    template = get_template(template_name, using=using)
  File "D:\python\Python27\lib\site-packages\django\template\loader.py", line 21, in get_template
    return engine.get_template(template_name)
  File "D:\python\Python27\lib\site-packages\django\template\backends\django.py", line 39, in get_template
    return Template(self.engine.get_template(template_name), self)
  File "D:\python\Python27\lib\site-packages\django\template\engine.py", line 160, in get_template
    template, origin = self.find_template(template_name)
  File "D:\python\Python27\lib\site-packages\django\template\engine.py", line 134, in find_template
    name, template_dirs=dirs, skip=skip,
  File "D:\python\Python27\lib\site-packages\django\template\loaders\base.py", line 44, in get_template
    contents, origin, origin.template_name, self.engine,
  File "D:\python\Python27\lib\site-packages\django\template\base.py", line 191, in __init__
    self.nodelist = self.compile_nodelist()
  File "D:\python\Python27\lib\site-packages\django\template\base.py", line 233, in compile_nodelist
    return parser.parse()
  File "D:\python\Python27\lib\site-packages\django\template\base.py", line 518, in parse
    raise self.error(token, e)
TemplateSyntaxError: Could not parse the remainder: '['url']' from 'inter['url']'
2016-09-28 11:32:48,786 [Thread-6:376] [django.request:124] [ERROR]- Internal Server Error: /lsinters/
Traceback (most recent call last):
  File "D:\python\Python27\lib\site-packages\django\core\handlers\exception.py", line 39, in inner
    response = get_response(request)
  File "D:\python\Python27\lib\site-packages\django\core\handlers\base.py", line 187, in _get_response
    response = self.process_exception_by_middleware(e, request)
  File "D:\python\Python27\lib\site-packages\django\core\handlers\base.py", line 185, in _get_response
    response = wrapped_callback(request, *callback_args, **callback_kwargs)
  File "F:\python-workspace\autotest\urlinter\views.py", line 32, in lsinters
    return render(request, 'inters.html', ctx)
  File "D:\python\Python27\lib\site-packages\django\shortcuts.py", line 30, in render
    content = loader.render_to_string(template_name, context, request, using=using)
  File "D:\python\Python27\lib\site-packages\django\template\loader.py", line 67, in render_to_string
    template = get_template(template_name, using=using)
  File "D:\python\Python27\lib\site-packages\django\template\loader.py", line 21, in get_template
    return engine.get_template(template_name)
  File "D:\python\Python27\lib\site-packages\django\template\backends\django.py", line 39, in get_template
    return Template(self.engine.get_template(template_name), self)
  File "D:\python\Python27\lib\site-packages\django\template\engine.py", line 160, in get_template
    template, origin = self.find_template(template_name)
  File "D:\python\Python27\lib\site-packages\django\template\engine.py", line 134, in find_template
    name, template_dirs=dirs, skip=skip,
  File "D:\python\Python27\lib\site-packages\django\template\loaders\base.py", line 44, in get_template
    contents, origin, origin.template_name, self.engine,
  File "D:\python\Python27\lib\site-packages\django\template\base.py", line 191, in __init__
    self.nodelist = self.compile_nodelist()
  File "D:\python\Python27\lib\site-packages\django\template\base.py", line 233, in compile_nodelist
    return parser.parse()
  File "D:\python\Python27\lib\site-packages\django\template\base.py", line 518, in parse
    raise self.error(token, e)
TemplateSyntaxError: Could not parse the remainder: '['url']' from 'inter['url']'
2016-09-28 11:33:03,773 [Thread-8:7596] [django.request:124] [ERROR]- Internal Server Error: /lsinters/
Traceback (most recent call last):
  File "D:\python\Python27\lib\site-packages\django\core\handlers\exception.py", line 39, in inner
    response = get_response(request)
  File "D:\python\Python27\lib\site-packages\django\core\handlers\base.py", line 187, in _get_response
    response = self.process_exception_by_middleware(e, request)
  File "D:\python\Python27\lib\site-packages\django\core\handlers\base.py", line 185, in _get_response
    response = wrapped_callback(request, *callback_args, **callback_kwargs)
  File "F:\python-workspace\autotest\urlinter\views.py", line 32, in lsinters
    return render(request, 'inters.html', ctx)
  File "D:\python\Python27\lib\site-packages\django\shortcuts.py", line 30, in render
    content = loader.render_to_string(template_name, context, request, using=using)
  File "D:\python\Python27\lib\site-packages\django\template\loader.py", line 67, in render_to_string
    template = get_template(template_name, using=using)
  File "D:\python\Python27\lib\site-packages\django\template\loader.py", line 21, in get_template
    return engine.get_template(template_name)
  File "D:\python\Python27\lib\site-packages\django\template\backends\django.py", line 39, in get_template
    return Template(self.engine.get_template(template_name), self)
  File "D:\python\Python27\lib\site-packages\django\template\engine.py", line 160, in get_template
    template, origin = self.find_template(template_name)
  File "D:\python\Python27\lib\site-packages\django\template\engine.py", line 134, in find_template
    name, template_dirs=dirs, skip=skip,
  File "D:\python\Python27\lib\site-packages\django\template\loaders\base.py", line 44, in get_template
    contents, origin, origin.template_name, self.engine,
  File "D:\python\Python27\lib\site-packages\django\template\base.py", line 191, in __init__
    self.nodelist = self.compile_nodelist()
  File "D:\python\Python27\lib\site-packages\django\template\base.py", line 233, in compile_nodelist
    return parser.parse()
  File "D:\python\Python27\lib\site-packages\django\template\base.py", line 518, in parse
    raise self.error(token, e)
TemplateSyntaxError: Could not parse the remainder: '['method']' from 'inter['method']'
2016-09-28 11:33:31,772 [Thread-10:6876] [django.request:124] [ERROR]- Internal Server Error: /lsinters/
Traceback (most recent call last):
  File "D:\python\Python27\lib\site-packages\django\core\handlers\exception.py", line 39, in inner
    response = get_response(request)
  File "D:\python\Python27\lib\site-packages\django\core\handlers\base.py", line 187, in _get_response
    response = self.process_exception_by_middleware(e, request)
  File "D:\python\Python27\lib\site-packages\django\core\handlers\base.py", line 185, in _get_response
    response = wrapped_callback(request, *callback_args, **callback_kwargs)
  File "F:\python-workspace\autotest\urlinter\views.py", line 32, in lsinters
    return render(request, 'inters.html', ctx)
  File "D:\python\Python27\lib\site-packages\django\shortcuts.py", line 30, in render
    content = loader.render_to_string(template_name, context, request, using=using)
  File "D:\python\Python27\lib\site-packages\django\template\loader.py", line 67, in render_to_string
    template = get_template(template_name, using=using)
  File "D:\python\Python27\lib\site-packages\django\template\loader.py", line 21, in get_template
    return engine.get_template(template_name)
  File "D:\python\Python27\lib\site-packages\django\template\backends\django.py", line 39, in get_template
    return Template(self.engine.get_template(template_name), self)
  File "D:\python\Python27\lib\site-packages\django\template\engine.py", line 160, in get_template
    template, origin = self.find_template(template_name)
  File "D:\python\Python27\lib\site-packages\django\template\engine.py", line 134, in find_template
    name, template_dirs=dirs, skip=skip,
  File "D:\python\Python27\lib\site-packages\django\template\loaders\base.py", line 44, in get_template
    contents, origin, origin.template_name, self.engine,
  File "D:\python\Python27\lib\site-packages\django\template\base.py", line 191, in __init__
    self.nodelist = self.compile_nodelist()
  File "D:\python\Python27\lib\site-packages\django\template\base.py", line 233, in compile_nodelist
    return parser.parse()
  File "D:\python\Python27\lib\site-packages\django\template\base.py", line 518, in parse
    raise self.error(token, e)
TemplateSyntaxError: Could not parse the remainder: '['url']' from 'inter['url']'
2016-09-28 12:29:40,237 [Thread-16:7196] [django.request:124] [ERROR]- Internal Server Error: /lsinters/
Traceback (most recent call last):
  File "D:\python\Python27\lib\site-packages\django\core\handlers\exception.py", line 39, in inner
    response = get_response(request)
  File "D:\python\Python27\lib\site-packages\django\core\handlers\base.py", line 187, in _get_response
    response = self.process_exception_by_middleware(e, request)
  File "D:\python\Python27\lib\site-packages\django\core\handlers\base.py", line 185, in _get_response
    response = wrapped_callback(request, *callback_args, **callback_kwargs)
  File "F:\python-workspace\autotest\urlinter\views.py", line 32, in lsinters
    return render(request, 'inters.html', ctx)
  File "D:\python\Python27\lib\site-packages\django\shortcuts.py", line 30, in render
    content = loader.render_to_string(template_name, context, request, using=using)
  File "D:\python\Python27\lib\site-packages\django\template\loader.py", line 67, in render_to_string
    template = get_template(template_name, using=using)
  File "D:\python\Python27\lib\site-packages\django\template\loader.py", line 21, in get_template
    return engine.get_template(template_name)
  File "D:\python\Python27\lib\site-packages\django\template\backends\django.py", line 39, in get_template
    return Template(self.engine.get_template(template_name), self)
  File "D:\python\Python27\lib\site-packages\django\template\engine.py", line 160, in get_template
    template, origin = self.find_template(template_name)
  File "D:\python\Python27\lib\site-packages\django\template\engine.py", line 134, in find_template
    name, template_dirs=dirs, skip=skip,
  File "D:\python\Python27\lib\site-packages\django\template\loaders\base.py", line 44, in get_template
    contents, origin, origin.template_name, self.engine,
  File "D:\python\Python27\lib\site-packages\django\template\base.py", line 191, in __init__
    self.nodelist = self.compile_nodelist()
  File "D:\python\Python27\lib\site-packages\django\template\base.py", line 233, in compile_nodelist
    return parser.parse()
  File "D:\python\Python27\lib\site-packages\django\template\base.py", line 518, in parse
    raise self.error(token, e)
TemplateSyntaxError: Could not parse the remainder: '['url']' from 'inter['url']'
2016-09-28 15:06:29,822 [Thread-13:6412] [django.request:124] [ERROR]- Internal Server Error: /lsresults/
Traceback (most recent call last):
  File "D:\python\Python27\lib\site-packages\django\core\handlers\exception.py", line 39, in inner
    response = get_response(request)
  File "D:\python\Python27\lib\site-packages\django\core\handlers\base.py", line 187, in _get_response
    response = self.process_exception_by_middleware(e, request)
  File "D:\python\Python27\lib\site-packages\django\core\handlers\base.py", line 185, in _get_response
    response = wrapped_callback(request, *callback_args, **callback_kwargs)
  File "F:\python-workspace\autotest\urlinter\views.py", line 59, in lsresults
    print("ctx:"+ctx)
TypeError: cannot concatenate 'str' and 'dict' objects
2016-09-29 13:47:51,230 [Thread-9:7488] [exception.handle_uncaught_exception:124] ERROR Internal Server Error: /lsresults/
Traceback (most recent call last):
  File "D:\python\Python27\lib\site-packages\django\core\handlers\exception.py", line 39, in inner
    response = get_response(request)
  File "D:\python\Python27\lib\site-packages\django\core\handlers\base.py", line 187, in _get_response
    response = self.process_exception_by_middleware(e, request)
  File "D:\python\Python27\lib\site-packages\django\core\handlers\base.py", line 185, in _get_response
    response = wrapped_callback(request, *callback_args, **callback_kwargs)
  File "F:\python-workspace\autotest\interapp\views.py", line 62, in lsresults
    return render(request, 'results.html', ctx)
  File "D:\python\Python27\lib\site-packages\django\shortcuts.py", line 30, in render
    content = loader.render_to_string(template_name, context, request, using=using)
  File "D:\python\Python27\lib\site-packages\django\template\loader.py", line 67, in render_to_string
    template = get_template(template_name, using=using)
  File "D:\python\Python27\lib\site-packages\django\template\loader.py", line 21, in get_template
    return engine.get_template(template_name)
  File "D:\python\Python27\lib\site-packages\django\template\backends\django.py", line 39, in get_template
    return Template(self.engine.get_template(template_name), self)
  File "D:\python\Python27\lib\site-packages\django\template\engine.py", line 160, in get_template
    template, origin = self.find_template(template_name)
  File "D:\python\Python27\lib\site-packages\django\template\engine.py", line 134, in find_template
    name, template_dirs=dirs, skip=skip,
  File "D:\python\Python27\lib\site-packages\django\template\loaders\base.py", line 44, in get_template
    contents, origin, origin.template_name, self.engine,
  File "D:\python\Python27\lib\site-packages\django\template\base.py", line 191, in __init__
    self.nodelist = self.compile_nodelist()
  File "D:\python\Python27\lib\site-packages\django\template\base.py", line 233, in compile_nodelist
    return parser.parse()
  File "D:\python\Python27\lib\site-packages\django\template\base.py", line 518, in parse
    raise self.error(token, e)
TemplateSyntaxError: Could not parse the remainder: '+result.server.name+'/'+result.inter.service+result.inter.path' from ''http:'+result.server.name+'/'+result.inter.service+result.inter.path'
2016-09-29 13:49:25,625 [Thread-2:6128] [exception.handle_uncaught_exception:124] ERROR Internal Server Error: /lsresults/
Traceback (most recent call last):
  File "D:\python\Python27\lib\site-packages\django\core\handlers\exception.py", line 39, in inner
    response = get_response(request)
  File "D:\python\Python27\lib\site-packages\django\core\handlers\base.py", line 187, in _get_response
    response = self.process_exception_by_middleware(e, request)
  File "D:\python\Python27\lib\site-packages\django\core\handlers\base.py", line 185, in _get_response
    response = wrapped_callback(request, *callback_args, **callback_kwargs)
  File "F:\python-workspace\autotest\interapp\views.py", line 62, in lsresults
    return render(request, 'results.html', ctx)
  File "D:\python\Python27\lib\site-packages\django\shortcuts.py", line 30, in render
    content = loader.render_to_string(template_name, context, request, using=using)
  File "D:\python\Python27\lib\site-packages\django\template\loader.py", line 67, in render_to_string
    template = get_template(template_name, using=using)
  File "D:\python\Python27\lib\site-packages\django\template\loader.py", line 21, in get_template
    return engine.get_template(template_name)
  File "D:\python\Python27\lib\site-packages\django\template\backends\django.py", line 39, in get_template
    return Template(self.engine.get_template(template_name), self)
  File "D:\python\Python27\lib\site-packages\django\template\engine.py", line 160, in get_template
    template, origin = self.find_template(template_name)
  File "D:\python\Python27\lib\site-packages\django\template\engine.py", line 134, in find_template
    name, template_dirs=dirs, skip=skip,
  File "D:\python\Python27\lib\site-packages\django\template\loaders\base.py", line 44, in get_template
    contents, origin, origin.template_name, self.engine,
  File "D:\python\Python27\lib\site-packages\django\template\base.py", line 191, in __init__
    self.nodelist = self.compile_nodelist()
  File "D:\python\Python27\lib\site-packages\django\template\base.py", line 233, in compile_nodelist
    return parser.parse()
  File "D:\python\Python27\lib\site-packages\django\template\base.py", line 518, in parse
    raise self.error(token, e)
TemplateSyntaxError: Could not parse the remainder: '+result.server.name+'/'+result.inter.service+result.inter.path' from ''http:'+result.server.name+'/'+result.inter.service+result.inter.path'
2016-09-29 14:04:28,003 [Thread-13:4200] [exception.handle_uncaught_exception:124] ERROR Internal Server Error: /lsresults/
Traceback (most recent call last):
  File "D:\python\Python27\lib\site-packages\django\core\handlers\exception.py", line 39, in inner
    response = get_response(request)
  File "D:\python\Python27\lib\site-packages\django\core\handlers\base.py", line 187, in _get_response
    response = self.process_exception_by_middleware(e, request)
  File "D:\python\Python27\lib\site-packages\django\core\handlers\base.py", line 185, in _get_response
    response = wrapped_callback(request, *callback_args, **callback_kwargs)
  File "F:\python-workspace\autotest\interapp\views.py", line 62, in lsresults
    return render(request, 'results.html', ctx)
  File "D:\python\Python27\lib\site-packages\django\shortcuts.py", line 30, in render
    content = loader.render_to_string(template_name, context, request, using=using)
  File "D:\python\Python27\lib\site-packages\django\template\loader.py", line 67, in render_to_string
    template = get_template(template_name, using=using)
  File "D:\python\Python27\lib\site-packages\django\template\loader.py", line 21, in get_template
    return engine.get_template(template_name)
  File "D:\python\Python27\lib\site-packages\django\template\backends\django.py", line 39, in get_template
    return Template(self.engine.get_template(template_name), self)
  File "D:\python\Python27\lib\site-packages\django\template\engine.py", line 160, in get_template
    template, origin = self.find_template(template_name)
  File "D:\python\Python27\lib\site-packages\django\template\engine.py", line 134, in find_template
    name, template_dirs=dirs, skip=skip,
  File "D:\python\Python27\lib\site-packages\django\template\loaders\base.py", line 44, in get_template
    contents, origin, origin.template_name, self.engine,
  File "D:\python\Python27\lib\site-packages\django\template\base.py", line 191, in __init__
    self.nodelist = self.compile_nodelist()
  File "D:\python\Python27\lib\site-packages\django\template\base.py", line 233, in compile_nodelist
    return parser.parse()
  File "D:\python\Python27\lib\site-packages\django\template\base.py", line 518, in parse
    raise self.error(token, e)
TemplateSyntaxError: Could not parse the remainder: '+result.server.name+'/'+result.inter.service+result.inter.path' from ''http:'+result.server.name+'/'+result.inter.service+result.inter.path'
2016-09-29 14:04:35,562 [Thread-15:6364] [base.get_response:152] WARNING Not Found: /execute
2016-09-29 14:08:35,881 [Thread-6:7080] [base.get_response:152] WARNING Not Found: /lsinters
2016-09-29 14:08:40,349 [Thread-17:6636] [base.get_response:152] WARNING Not Found: /lsinters
2016-09-29 14:11:40,186 [Thread-12:6316] [exception.handle_uncaught_exception:124] ERROR Internal Server Error: /lsresults.do
Traceback (most recent call last):
  File "D:\python\Python27\lib\site-packages\django\core\handlers\exception.py", line 39, in inner
    response = get_response(request)
  File "D:\python\Python27\lib\site-packages\django\core\handlers\base.py", line 187, in _get_response
    response = self.process_exception_by_middleware(e, request)
  File "D:\python\Python27\lib\site-packages\django\core\handlers\base.py", line 185, in _get_response
    response = wrapped_callback(request, *callback_args, **callback_kwargs)
  File "F:\python-workspace\autotest\interapp\views.py", line 62, in lsresults
    return render(request, 'results.html', ctx)
  File "D:\python\Python27\lib\site-packages\django\shortcuts.py", line 30, in render
    content = loader.render_to_string(template_name, context, request, using=using)
  File "D:\python\Python27\lib\site-packages\django\template\loader.py", line 67, in render_to_string
    template = get_template(template_name, using=using)
  File "D:\python\Python27\lib\site-packages\django\template\loader.py", line 21, in get_template
    return engine.get_template(template_name)
  File "D:\python\Python27\lib\site-packages\django\template\backends\django.py", line 39, in get_template
    return Template(self.engine.get_template(template_name), self)
  File "D:\python\Python27\lib\site-packages\django\template\engine.py", line 160, in get_template
    template, origin = self.find_template(template_name)
  File "D:\python\Python27\lib\site-packages\django\template\engine.py", line 134, in find_template
    name, template_dirs=dirs, skip=skip,
  File "D:\python\Python27\lib\site-packages\django\template\loaders\base.py", line 44, in get_template
    contents, origin, origin.template_name, self.engine,
  File "D:\python\Python27\lib\site-packages\django\template\base.py", line 191, in __init__
    self.nodelist = self.compile_nodelist()
  File "D:\python\Python27\lib\site-packages\django\template\base.py", line 233, in compile_nodelist
    return parser.parse()
  File "D:\python\Python27\lib\site-packages\django\template\base.py", line 518, in parse
    raise self.error(token, e)
TemplateSyntaxError: Could not parse the remainder: '+result.server.name+'/'+result.inter.service+result.inter.path' from ''http:'+result.server.name+'/'+result.inter.service+result.inter.path'
2016-09-29 14:20:15,584 [Thread-14:7996] [base.get_response:152] WARNING Not Found: /lsresults/
2016-09-29 14:20:20,529 [Thread-24:8104] [exception.handle_uncaught_exception:124] ERROR Internal Server Error: /lsresults.do
Traceback (most recent call last):
  File "D:\python\Python27\lib\site-packages\django\core\handlers\exception.py", line 39, in inner
    response = get_response(request)
  File "D:\python\Python27\lib\site-packages\django\core\handlers\base.py", line 187, in _get_response
    response = self.process_exception_by_middleware(e, request)
  File "D:\python\Python27\lib\site-packages\django\core\handlers\base.py", line 185, in _get_response
    response = wrapped_callback(request, *callback_args, **callback_kwargs)
  File "F:\python-workspace\autotest\interapp\views.py", line 62, in lsresults
    return render(request, 'results.html', ctx)
  File "D:\python\Python27\lib\site-packages\django\shortcuts.py", line 30, in render
    content = loader.render_to_string(template_name, context, request, using=using)
  File "D:\python\Python27\lib\site-packages\django\template\loader.py", line 67, in render_to_string
    template = get_template(template_name, using=using)
  File "D:\python\Python27\lib\site-packages\django\template\loader.py", line 21, in get_template
    return engine.get_template(template_name)
  File "D:\python\Python27\lib\site-packages\django\template\backends\django.py", line 39, in get_template
    return Template(self.engine.get_template(template_name), self)
  File "D:\python\Python27\lib\site-packages\django\template\engine.py", line 160, in get_template
    template, origin = self.find_template(template_name)
  File "D:\python\Python27\lib\site-packages\django\template\engine.py", line 134, in find_template
    name, template_dirs=dirs, skip=skip,
  File "D:\python\Python27\lib\site-packages\django\template\loaders\base.py", line 44, in get_template
    contents, origin, origin.template_name, self.engine,
  File "D:\python\Python27\lib\site-packages\django\template\base.py", line 191, in __init__
    self.nodelist = self.compile_nodelist()
  File "D:\python\Python27\lib\site-packages\django\template\base.py", line 233, in compile_nodelist
    return parser.parse()
  File "D:\python\Python27\lib\site-packages\django\template\base.py", line 518, in parse
    raise self.error(token, e)
TemplateSyntaxError: Could not parse the remainder: '+result.server.name+'/'+result.inter.service+result.inter.path' from ''http:'+result.server.name+'/'+result.inter.service+result.inter.path'
2016-09-29 20:39:53,650 [Thread-53:6812] [base.get_response:152] WARNING Not Found: /execute.do
2016-09-29 20:40:25,391 [Thread-55:2452] [base.get_response:152] WARNING Not Found: /execute.do
2016-09-29 20:41:39,674 [Thread-14:8948] [csrf._reject:158] WARNING Forbidden (CSRF token missing or incorrect.): /execute.do
2016-09-29 20:43:08,013 [Thread-28:6292] [csrf._reject:158] WARNING Forbidden (CSRF token missing or incorrect.): /execute.do
2016-09-29 20:44:55,762 [Thread-16:8228] [csrf._reject:158] WARNING Forbidden (CSRF token missing or incorrect.): /execute.do
2016-09-29 20:46:08,992 [Thread-32:8636] [csrf._reject:158] WARNING Forbidden (CSRF token missing or incorrect.): /execute.do
2016-09-29 20:48:22,806 [Thread-15:8768] [csrf._reject:158] WARNING Forbidden (CSRF token missing or incorrect.): /execute.do
2016-09-29 20:53:10,930 [Thread-15:9080] [csrf._reject:158] WARNING Forbidden (CSRF token missing or incorrect.): /execute.do
2016-09-29 20:53:42,969 [Thread-15:8944] [csrf._reject:158] WARNING Forbidden (CSRF token missing or incorrect.): /execute.do
